Workbook

Sheet Read Me
B2: Estimating the initial number of dwelllings and replacement projects that occur over time
A3: 1 | B3: The number of projects/annum for a given area is the SUM OF renovations AND new builds (see below).
B4: NOTE: renovations occur at specified intervals after a dwelling has been built. For example, if kitchens are replaced every 30 years (for example), 30 years, 60 years, etc later, a kitchen renovation will occur.
B5: NOTE: an area may be too new for the renovation cycle to have commenced.
A6: 2 | B6: The number of projects in an area which are renovations/renewals is directly related to the number of dwellings built when that area was first developed.
A7: 3 | B7: Key inputs are:
B8: Start Date of major development (when residential blocks were first created as part of an urbanisation project)
B9: Finish Date of major development (when the area area is, say, 70 to 80% developed)
B10: Project life (ie how often does a kitchen or driveway or boundary fence, etc, have to be replaced)
A11: 4 | B11: The earliest available LGA data is for 1961. The earliest, easily obtainable Postcode data is for 2001.
B12: The earliest Start Date available is 1901 (this is a model limitation).
B13: The earliest Finish Date is 1961 (this is a data limitation - no data prior to 1961).
A14: 5 | B14: By fitting a curve to the 2001-2021 Postcode data, estimates of the number of dwellings in that Postcode prior to 2001 can be made:
B15: For long-developed Postcodes (eg 50 years +), the estimate for pre-2021 may be quite accurate
B16: but only if the LGA in which the Postcode sits is also long-developed
B17: For relatively newly developed Postcodes, the estimates may be a little to a long way off
A18: 6 | B18: An alternative to curve fitting is to use the percentage contribution of a Postcode in a LGA to estimate the number of dwellings in that Postcode prior to 2001.
B19: If all Postcodes in a LGA were developed at the same time, this approach will work, otherwise it willl cause discrepancies; the earlier the Finish Date,
B20: the greater the discrepancy.
A21: 7 | B21: HOW IT WORKS: the number of dwelllings available on the Finish Date drives all the calculations. That number is apportioned over the build-up period - which is the time between the Start Date abd the Finish Date.
B22: EXAMPLE: Dwelllings at Finish Date = 1,000. Build-up period = 10 years. Dwellings added each year = 100. If kitchens are replaced every 30 years (on average), then 30 years after each increment of 100 dwellings added during the build-up period,
B23: 100 kitchens will be required. NOTE: not all projects have a 100% uptake.
A24: 8 | B24: If the time taken to develop a Postcode (the build-up period) is less than the project life, the number of replacements will be lumpy because replacements will not be required for the dwellings added in the early years of the build-up until after the Finish Date
B25: EXAMPLE: if the build-up period is 20 years and the replacement period is 40 years, there will be a 20 year periods when no replacements occur.
A26: 9 | B26: The rate at which projects are adopted can vary over time. Some projects, eg kitchens, bathrooms, etc always have a 100% uptake but others do not. Some projects may start with an uptake = 0% (eg ducted air conditioning in 1970) but increase over time.
B27: A change in update applies to all the dwellings available on the Finish Date.
B28: EXAMPLE: say the uptake rate for simming pools in 1961 is 0% but that it increases slowly from 0% in 1980 to 3% in 2024. The replacement period (the project life) is used to forecast activity levels from the Finish Date. That activity is multipled by the uptake rate.
A29: 10 | B29: Uptake rates can increase, decrease or stay constant. For example, in some cities virtually all detached dwellings built prior to 1960 had terracotta roofs. When those roofs were replaced options were terracotta, concrete tiles and metal.
B30: Where there are options available, the sum of those options must be 100%.
B33: Projects resulting from new builds (after major development finishes) can take 3 forms
B34: If the number of dwellings in an area continues to rise after the Finish Date, the increase is treated as a new build. An increase in the number of detached dwellings will be due to blocks being reduced in size (eg the creation of battle-axe blocks), etc.
B35: An increase in total dwellings will be due to an increase in detached dwellings and/or the development of medium and hgh density zones. Medium and high density may (or will) reduce the number of detached dwellings but in most Postcodes the impact will be slight.
B37: New build options:
A38: 1 | B38: Projects where uptake can go up and down, eg a gravel driveway replaced with bitumen then replaced with concrete. The level of uptake may/will change from year to year depending on cost, trends, etc. The sum of the options must be 100%..
A39: 2 | B39: Projects where additions occur in the first year, are permanent and cannot be removed or changed over time, eg ensuites, laundries. The level of uptake may vary for dwellings built in one year compared to dwelllings built in another year.
B40: The important point about this category is that once the percentage is determined for new builds of a particular year, it does not chanhe over time (up or down).
A41: 3 | B41: Projects where additions may occur at any time but are not reversed, eg air conditioning, front fences, swimming pools. Once the feature is added it is never removed, so uptake for dwellings built in a particular year may/will grow over time as more projects are added.

Sheet Master
B2: Internal projects | E2: External projects
A3: 1 | B3: Aircon - wall mounted | D3: 16 | E3: Decking/verandah
A4: =A3+1 -> 2 | B4: Aircon - ducted | D4: =D3+1 -> 17 | E4: Driveway - aggregate | L4: Data used | N4: WA | O4: (AUS, WA, 6008 to 6011, NSW, 2070 to 2075)
A5: =A4+1 -> 3 | B5: Bathroom - main | D5: =D4+1 -> 18 | E5: Driveway - brick/paver
A6: =A5+1 -> 4 | B6: Bathroom - ensuite | D6: =D5+1 -> 19 | E6: Driveway - bitumen
A7: =A6+1 -> 5 | B7: Flooring - timber | D7: =D6+1 -> 20 | E7: Driveway - concrete
A8: =A7+1 -> 6 | B8: Floring - carpet | D8: =D7+1 -> 21 | E8: Fencing - front
A9: =A8+1 -> 7 | B9: Floring - ceramic tile | D9: =D8+1 -> 22 | E9: Fencing - rear/sides
A10: =A9+1 -> 8 | B10: Flooring - vinyl tile | D10: =D9+1 -> 23 | E10: Fencing - pool
A11: =A10+1 -> 9 | B11: Home comms | D11: =D10+1 -> 24 | E11: Gutters/downpipes | V11: NOTE:
A12: =A11+1 -> 10 | B12: Home security | D12: =D11+1 -> 25 | E12: Gates - security | L12: Start of major development (or Build-up) | Q12: 1901 | R12: (1901 is the earliest start date) | V12: If the Build-up (or development) period is
A13: =A12+1 -> 11 | B13: Kitchen | D13: =D12+1 -> 26 | E13: Painting (exterior) | L13: Finish of major development (or Build-up) | Q13: 1961 | R13: (1961 is earliest finish date) | V13: LESS THAN the product life, there will be a
A14: =A13+1 -> 12 | B14: Laundry | D14: =D13+1 -> 27 | E14: Paving/patio | L14: Build-up period | Q14: =Q13-Q12 -> 60 | V14: period of no replacement projects for
A15: =A14+1 -> 13 | B15: Painting (interior) | D15: =D14+1 -> 28 | E15: Pergola | L15: Product life | Q15: =D169 -> 35 | R15: (At development Finish Date) | V15: =B27&", but after that period end," -> Pre 1961 stock, but after that period end,
A16: =A15+1 -> 14 | B16: Wardrobes - built-in | D16: =D15+1 -> 29 | E16: Pool | V16: projects will continue
A17: =A16+1 -> 15 | B17: Wardrobes - walk-in | D17: =D16+1 -> 30 | E17: Roof - metal | L17: =B26 -> Source of potential projects (ALL dwellings) | Q17: 2024
D18: =D17+1 -> 31 | E18: Roof - concrete tile | L18: =B27 -> Pre 1961 stock | Q18: =F27 -> 30935.066
D19: =D18+1 -> 32 | E19: Roof - terracotta tile | L19: =B28 -> Post 1961 additions | Q19: =F28-F31 -> 22507.149
D20: =D19+1 -> 33 | E20: Roof - other | L20: =B31 -> New builds - 2024 | Q20: =F31 -> 36186.779
D21: 34 | E21: Solar - battery | Q21: =SUM(Q18:Q20) -> 89628.993
D22: 35 | E22: Solar - panels
A24: => | B24: Project number selected | C24: 3 | D24: =IF(AND(C24>=1,C24<=15),VLOOKUP(C24,$A$3:$B$17,2,TRUE),VLOOKUP(C24,$D$3:$E$22,2,TRUE)) -> Bathroom - main
B26: =IF(C354=1,"Source of potential projects (ALL dwellings)","Source of potential projects (DETACHED dwellings)") -> Source of potential projects (ALL dwellings) | D26: 2022 | E26: 2023 | F26: =2024 -> 2024 | G26: 2025 | H26: 2026 | L26: Projects resulting from new builds (after major development finishes) can take 3 forms
B27: ="Pre "&Q13&" stock" -> Pre 1961 stock | C27: # | D27: =DU772*1000 -> 30935.066 | E27: =DV772*1000 -> 30935.066 | F27: =DW772*1000 -> 30935.066 | G27: =DX772*1000 -> 30935.066 | H27: =DY772*1000 -> 46402.598 | K27: 1 | L27: Projects where uptake can go up and down, eg gravel driveway replaced with bitumen replaced with concrete
A28: + | B28: ="Post "&Q13&" additions" -> Post 1961 additions | C28: # | D28: =IF($O34=1,DU1171,IF($O34=2,DU1308,DU1445))*1000 -> 58693.928 | E28: =IF($O34=1,DV1171,IF($O34=2,DV1308,DV1445))*1000 -> 58693.928 | F28: =IF($O34=1,DW1171,IF($O34=2,DW1308,DW1445))*1000 -> 58693.928 | G28: =IF($O34=1,DX1171,IF($O34=2,DX1308,DX1445))*1000 -> 58693.928 | H28: =IF($O34=1,DY1171,IF($O34=2,DY1308,DY1445))*1000 -> 91300.477 | L28: The level of uptake may/will change from year to year
A29: = | B29: Total projects | C29: # | D29: =D27+D28 -> 89628.993 | E29: =E27+E28 -> 89628.993 | F29: =F27+F28 -> 89628.993 | G29: =G27+G28 -> 89628.993 | H29: =H27+H28 -> 137703.08 | K29: 2 | L29: Projects where additions occur in the first year, are permanent and cannot be removed or changed over time, eg ensuites, laundries
L30: The level of uptake may vary for dwellings built in one year compared to dwelllings built in another year. Within a particular group of dwellings there is no change
A31: => | B31: New builds - 2024 | C31: # | D31: =IF($O34=1,DU1176,IF($O34=2,DU1311,DU1448))*1000 -> 36186.779 | E31: =IF($O34=1,DV1176,IF($O34=2,DV1311,DV1448))*1000 -> 36186.779 | F31: =IF($O34=1,DW1176,IF($O34=2,DW1311,DW1448))*1000 -> 36186.779 | G31: =IF($O34=1,DX1176,IF($O34=2,DX1311,DX1448))*1000 -> 36186.779 | H31: =IF($O34=1,DY1176,IF($O34=2,DY1311,DY1448))*1000 -> 39135.148 | K31: 3 | L31: Projects where additions may occur at any time but are not reversed, eg air conditioning, front fences, swimming pools
A32: => | B32: Replacements | C32: # | D32: =D29-D31 -> 53442.214 | E32: =E29-E31 -> 53442.214 | F32: =F29-F31 -> 53442.214 | G32: =G29-G31 -> 53442.214 | H32: =H29-H31 -> 98567.928 | L32: Once the feature is added it is not removed, so uptake for dwellings built in a particular year may/will grow over time
A33: => | B33: Total projects | C33: # | D33: =D31+D32 -> 89628.993 | E33: =E31+E32 -> 89628.993 | F33: =F31+F32 -> 89628.993 | G33: =G31+G32 -> 89628.993 | H33: =H31+H32 -> 137703.08
K34: => | L34: New build AUTO selection | O34: =IF(AND($C$24>=1,$C$24<=15),VLOOKUP($C$24,$A$261:$C$274,C$259,TRUE),VLOOKUP($C$24,$A$297:$C$316,C$259,TRUE)) -> 2
A35: => | B35: =IF(C354=1,"As a % of ALL existing dwellings","As a % of existing DETACHED dwellings") -> As a % of ALL existing dwellings | D35: =IF($C354=1,D32/(#REF!*1000),D32/(#REF!*1000)) -> #REF! | E35: =IF($C354=1,E32/(#REF!*1000),E32/(#REF!*1000)) -> #REF! | F35: =IF($C354=1,F32/(#REF!*1000),F32/(#REF!*1000)) -> #REF! | G35: =IF($C354=1,G32/(#REF!*1000),G32/(#REF!*1000)) -> #REF! | H35: =IF($C354=1,H32/(#REF!*1000),H32/(#REF!*1000)) -> #REF!
B37: Uptake | D37: =DU771 -> 1 | E37: =DV771 -> 1 | F37: =DW771 -> 1 | G37: =DX771 -> 1 | H37: =DY771 -> 1
B38: Product life | C38: years | D38: =DU508 -> 30 | E38: =DV508 -> 30 | F38: =DW508 -> 30 | G38: =DX508 -> 30 | H38: =DY508 -> 30
B43: Uptake = Proportion of dwellings with projects; can range from 100% to 10% or less
B44: Life = Average time a product or project lasts; can range from 60 years to 10 years
B47: Internal projects | C47: Uptake/Life | D47: 1901 | E47: =D47+1 -> 1902 | F47: =E47+1 -> 1903 | G47: =F47+1 -> 1904 | H47: =G47+1 -> 1905 | I47: =H47+1 -> 1906 | J47: =I47+1 -> 1907 | K47: =J47+1 -> 1908 | L47: =K47+1 -> 1909 | ... EC47: =EB47+1 -> 2030
A48: 1 | B48: Air con - wall | C48: uptake - original | D48: 0 | E48: =D48 -> 0 | F48: =E48 -> 0 | G48: =F48 -> 0 | H48: 0 | I48: =H48-((H48-M48)/5) -> 0 | J48: =I48-((H48-M48)/5) -> 0 | K48: =J48-((H48-M48)/5) -> 0 | L48: =K48-((H48-M48)/5) -> 0 | M48: 0 | N48: =M48-((M48-R48)/5) -> 0 | O48: =N48-((M48-R48)/5) -> 0 | P48: =O48-((M48-R48)/5) -> 0 | Q48: =P48-((M48-R48)/5) -> 0 | R48: 0 | S48: =R48-((R48-W48)/5) -> 0 | T48: =S48-((R48-W48)/5) -> 0 | U48: =T48-((R48-W48)/5) -> 0 | V48: =U48-((R48-W48)/5) -> 0 | W48: 0 | X48: =W48-((W48-AB48)/5) -> 0 | Y48: =X48-((W48-AB48)/5) -> 0 | Z48: =Y48-((W48-AB48)/5) -> 0 | AA48: =Z48-((W48-AB48)/5) -> 0 | AB48: 0 | AC48: =AB48-((AB48-AG48)/5) -> 0 | AD48: =AC48-((AB48-AG48)/5) -> 0 | AE48: =AD48-((AB48-AG48)/5) -> 0 | AF48: =AE48-((AB48-AG48)/5) -> 0 | AG48: 0 | AH48: =AG48-((AG48-AL48)/5) -> 0 | AI48: =AH48-((AG48-AL48)/5) -> 0 | AJ48: =AI48-((AG48-AL48)/5) -> 0 | AK48: =AJ48-((AG48-AL48)/5) -> 0 | AL48: 0 | AM48: =AL48-((AL48-AQ48)/5) -> 0 | AN48: =AM48-((AL48-AQ48)/5) -> 0 | AO48: =AN48-((AL48-AQ48)/5) -> 0 | AP48: =AO48-((AL48-AQ48)/5) -> 0 | AQ48: 0 | AR48: =AQ48-((AQ48-AV48)/5) -> 0 | AS48: =AR48-((AQ48-AV48)/5) -> 0 | AT48: =AS48-((AQ48-AV48)/5) -> 0 | AU48: =AT48-((AQ48-AV48)/5) -> 0 | AV48: 0 | AW48: =AV48-((AV48-BA48)/5) -> 0 | AX48: =AW48-((AV48-BA48)/5) -> 0 | AY48: =AX48-((AV48-BA48)/5) -> 0 | AZ48: =AY48-((AV48-BA48)/5) -> 0 | BA48: 0 | BB48: =BA48-((BA48-BF48)/5) -> 0 | BC48: =BB48-((BA48-BF48)/5) -> 0 | BD48: =BC48-((BA48-BF48)/5) -> 0 | BE48: =BD48-((BA48-BF48)/5) -> 0 | BF48: 0 | BG48: =BF48-((BF48-BK48)/5) -> 0 | BH48: =BG48-((BF48-BK48)/5) -> 0 | BI48: =BH48-((BF48-BK48)/5) -> 0 | BJ48: =BI48-((BF48-BK48)/5) -> 0 | BK48: 0 | BL48: =BK48-((BK48-BP48)/5) -> 0 | BM48: =BL48-((BK48-BP48)/5) -> 0 | BN48: =BM48-((BK48-BP48)/5) -> 0 | BO48: =BN48-((BK48-BP48)/5) -> 0 | BP48: 0 | BQ48: =BP48-((BP48-BU48)/5) -> 0 | BR48: =BQ48-((BP48-BU48)/5) -> 0 | BS48: =BR48-((BP48-BU48)/5) -> 0 | BT48: =BS48-((BP48-BU48)/5) -> 0 | BU48: 0 | BV48: =BU48-((BU48-BZ48)/5) -> 0 | BW48: =BV48-((BU48-BZ48)/5) -> 0 | BX48: =BW48-((BU48-BZ48)/5) -> 0 | BY48: =BX48-((BU48-BZ48)/5) -> 0 | BZ48: 0 | CA48: =BZ48-((BZ48-CE48)/5) -> 0 | CB48: =CA48-((BZ48-CE48)/5) -> 0 | CC48: =CB48-((BZ48-CE48)/5) -> 0 | CD48: =CC48-((BZ48-CE48)/5) -> 0 | CE48: 0 | CF48: =CE48-((CE48-CJ48)/5) -> 0 | CG48: =CF48-((CE48-CJ48)/5) -> 0 | CH48: =CG48-((CE48-CJ48)/5) -> 0 | CI48: =CH48-((CE48-CJ48)/5) -> 0 | CJ48: 0 | CK48: =CJ48-((CJ48-CO48)/5) -> 0.01 | CL48: =CK48-((CJ48-CO48)/5) -> 0.02 | CM48: =CL48-((CJ48-CO48)/5) -> 0.03 | CN48: =CM48-((CJ48-CO48)/5) -> 0.04 | CO48: 0.05 | CP48: =CO48-((CO48-CT48)/5) -> 0.06 | CQ48: =CP48-((CO48-CT48)/5) -> 0.07 | CR48: =CQ48-((CO48-CT48)/5) -> 0.08 | CS48: =CR48-((CO48-CT48)/5) -> 0.09 | CT48: 0.1 | CU48: =CT48-((CT48-CY48)/5) -> 0.12 | CV48: =CU48-((CT48-CY48)/5) -> 0.14 | CW48: =CV48-((CT48-CY48)/5) -> 0.16 | CX48: =CW48-((CT48-CY48)/5) -> 0.18 | CY48: 0.2 | CZ48: =CY48-((CY48-DD48)/5) -> 0.22 | DA48: =CZ48-((CY48-DD48)/5) -> 0.24 | DB48: =DA48-((CY48-DD48)/5) -> 0.26 | DC48: =DB48-((CY48-DD48)/5) -> 0.28 | DD48: 0.3 | DE48: =DD48-((DD48-DI48)/5) -> 0.32 | DF48: =DE48-((DD48-DI48)/5) -> 0.34 | DG48: =DF48-((DD48-DI48)/5) -> 0.36 | DH48: =DG48-((DD48-DI48)/5) -> 0.38 | DI48: 0.4 | DJ48: =DI48-((DI48-DN48)/5) -> 0.42 | DK48: =DJ48-((DI48-DN48)/5) -> 0.44 | DL48: =DK48-((DI48-DN48)/5) -> 0.46 | DM48: =DL48-((DI48-DN48)/5) -> 0.48 | DN48: 0.5 | DO48: =DN48-((DN48-DS48)/5) -> 0.51 | DP48: =DO48-((DN48-DS48)/5) -> 0.52 | DQ48: =DP48-((DN48-DS48)/5) -> 0.53 | DR48: =DQ48-((DN48-DS48)/5) -> 0.54 | DS48: 0.55 | DT48: =DS48-((DS48-DX48)/5) -> 0.56 | DU48: =DT48-((DS48-DX48)/5) -> 0.57 | DV48: =DU48-((DS48-DX48)/5) -> 0.58 | DW48: =DV48-((DS48-DX48)/5) -> 0.59 | DX48: 0.6 | DY48: =DX48-((DX48-EC48)/5) -> 0.6 | DZ48: =DY48-((DX48-EC48)/5) -> 0.6 | EA48: =DZ48-((DX48-EC48)/5) -> 0.6 | EB48: =EA48-((DX48-EC48)/5) -> 0.6 | EC48: 0.6
C49: uptake - new | D49: 0 | E49: =D49 -> 0 | F49: =E49 -> 0 | G49: =F49 -> 0 | H49: 0 | I49: =H49-((H49-M49)/5) -> 0 | J49: =I49-((H49-M49)/5) -> 0 | K49: =J49-((H49-M49)/5) -> 0 | L49: =K49-((H49-M49)/5) -> 0 | M49: 0 | N49: =M49-((M49-R49)/5) -> 0 | O49: =N49-((M49-R49)/5) -> 0 | P49: =O49-((M49-R49)/5) -> 0 | Q49: =P49-((M49-R49)/5) -> 0 | R49: 0 | S49: =R49-((R49-W49)/5) -> 0 | T49: =S49-((R49-W49)/5) -> 0 | U49: =T49-((R49-W49)/5) -> 0 | V49: =U49-((R49-W49)/5) -> 0 | W49: 0 | X49: =W49-((W49-AB49)/5) -> 0 | Y49: =X49-((W49-AB49)/5) -> 0 | Z49: =Y49-((W49-AB49)/5) -> 0 | AA49: =Z49-((W49-AB49)/5) -> 0 | AB49: 0 | AC49: =AB49-((AB49-AG49)/5) -> 0 | AD49: =AC49-((AB49-AG49)/5) -> 0 | AE49: =AD49-((AB49-AG49)/5) -> 0 | AF49: =AE49-((AB49-AG49)/5) -> 0 | AG49: 0 | AH49: =AG49-((AG49-AL49)/5) -> 0 | AI49: =AH49-((AG49-AL49)/5) -> 0 | AJ49: =AI49-((AG49-AL49)/5) -> 0 | AK49: =AJ49-((AG49-AL49)/5) -> 0 | AL49: 0 | AM49: =AL49-((AL49-AQ49)/5) -> 0 | AN49: =AM49-((AL49-AQ49)/5) -> 0 | AO49: =AN49-((AL49-AQ49)/5) -> 0 | AP49: =AO49-((AL49-AQ49)/5) -> 0 | AQ49: 0 | AR49: =AQ49-((AQ49-AV49)/5) -> 0 | AS49: =AR49-((AQ49-AV49)/5) -> 0 | AT49: =AS49-((AQ49-AV49)/5) -> 0 | AU49: =AT49-((AQ49-AV49)/5) -> 0 | AV49: 0 | AW49: =AV49-((AV49-BA49)/5) -> 0 | AX49: =AW49-((AV49-BA49)/5) -> 0 | AY49: =AX49-((AV49-BA49)/5) -> 0 | AZ49: =AY49-((AV49-BA49)/5) -> 0 | BA49: 0 | BB49: =BA49-((BA49-BF49)/5) -> 0 | BC49: =BB49-((BA49-BF49)/5) -> 0 | BD49: =BC49-((BA49-BF49)/5) -> 0 | BE49: =BD49-((BA49-BF49)/5) -> 0 | BF49: 0 | BG49: =BF49-((BF49-BK49)/5) -> 0 | BH49: =BG49-((BF49-BK49)/5) -> 0 | BI49: =BH49-((BF49-BK49)/5) -> 0 | BJ49: =BI49-((BF49-BK49)/5) -> 0 | BK49: 0 | BL49: =BK49-((BK49-BP49)/5) -> 0 | BM49: =BL49-((BK49-BP49)/5) -> 0 | BN49: =BM49-((BK49-BP49)/5) -> 0 | BO49: =BN49-((BK49-BP49)/5) -> 0 | BP49: 0 | BQ49: =BP49-((BP49-BU49)/5) -> 0 | BR49: =BQ49-((BP49-BU49)/5) -> 0 | BS49: =BR49-((BP49-BU49)/5) -> 0 | BT49: =BS49-((BP49-BU49)/5) -> 0 | BU49: 0 | BV49: =BU49-((BU49-BZ49)/5) -> 0 | BW49: =BV49-((BU49-BZ49)/5) -> 0 | BX49: =BW49-((BU49-BZ49)/5) -> 0 | BY49: =BX49-((BU49-BZ49)/5) -> 0 | BZ49: 0 | CA49: =BZ49-((BZ49-CE49)/5) -> 0 | CB49: =CA49-((BZ49-CE49)/5) -> 0 | CC49: =CB49-((BZ49-CE49)/5) -> 0 | CD49: =CC49-((BZ49-CE49)/5) -> 0 | CE49: 0 | CF49: =CE49-((CE49-CJ49)/5) -> 0 | CG49: =CF49-((CE49-CJ49)/5) -> 0 | CH49: =CG49-((CE49-CJ49)/5) -> 0 | CI49: =CH49-((CE49-CJ49)/5) -> 0 | CJ49: 0 | CK49: =CJ49-((CJ49-CO49)/5) -> 0.01 | CL49: =CK49-((CJ49-CO49)/5) -> 0.02 | CM49: =CL49-((CJ49-CO49)/5) -> 0.03 | CN49: =CM49-((CJ49-CO49)/5) -> 0.04 | CO49: 0.05 | CP49: =CO49-((CO49-CT49)/5) -> 0.06 | CQ49: =CP49-((CO49-CT49)/5) -> 0.07 | CR49: =CQ49-((CO49-CT49)/5) -> 0.08 | CS49: =CR49-((CO49-CT49)/5) -> 0.09 | CT49: 0.1 | CU49: =CT49-((CT49-CY49)/5) -> 0.12 | CV49: =CU49-((CT49-CY49)/5) -> 0.14 | CW49: =CV49-((CT49-CY49)/5) -> 0.16 | CX49: =CW49-((CT49-CY49)/5) -> 0.18 | CY49: 0.2 | CZ49: =CY49-((CY49-DD49)/5) -> 0.22 | DA49: =CZ49-((CY49-DD49)/5) -> 0.24 | DB49: =DA49-((CY49-DD49)/5) -> 0.26 | DC49: =DB49-((CY49-DD49)/5) -> 0.28 | DD49: 0.3 | DE49: =DD49-((DD49-DI49)/5) -> 0.32 | DF49: =DE49-((DD49-DI49)/5) -> 0.34 | DG49: =DF49-((DD49-DI49)/5) -> 0.36 | DH49: =DG49-((DD49-DI49)/5) -> 0.38 | DI49: 0.4 | DJ49: =DI49-((DI49-DN49)/5) -> 0.42 | DK49: =DJ49-((DI49-DN49)/5) -> 0.44 | DL49: =DK49-((DI49-DN49)/5) -> 0.46 | DM49: =DL49-((DI49-DN49)/5) -> 0.48 | DN49: 0.5 | DO49: =DN49-((DN49-DS49)/5) -> 0.51 | DP49: =DO49-((DN49-DS49)/5) -> 0.52 | DQ49: =DP49-((DN49-DS49)/5) -> 0.53 | DR49: =DQ49-((DN49-DS49)/5) -> 0.54 | DS49: 0.55 | DT49: =DS49-((DS49-DX49)/5) -> 0.56 | DU49: =DT49-((DS49-DX49)/5) -> 0.57 | DV49: =DU49-((DS49-DX49)/5) -> 0.58 | DW49: =DV49-((DS49-DX49)/5) -> 0.59 | DX49: 0.6 | DY49: =DX49-((DX49-EC49)/5) -> 0.6 | DZ49: =DY49-((DX49-EC49)/5) -> 0.6 | EA49: =DZ49-((DX49-EC49)/5) -> 0.6 | EB49: =EA49-((DX49-EC49)/5) -> 0.6 | EC49: 0.6
C50: life | D50: 0 | E50: =D50 -> 0 | F50: =E50 -> 0 | G50: =F50 -> 0 | H50: 0 | I50: =H50-((H50-M50)/5) -> 0 | J50: =I50-((H50-M50)/5) -> 0 | K50: =J50-((H50-M50)/5) -> 0 | L50: =K50-((H50-M50)/5) -> 0 | M50: 0 | N50: =M50-((M50-R50)/5) -> 0 | O50: =N50-((M50-R50)/5) -> 0 | P50: =O50-((M50-R50)/5) -> 0 | Q50: =P50-((M50-R50)/5) -> 0 | R50: 0 | S50: =R50-((R50-W50)/5) -> 0 | T50: =S50-((R50-W50)/5) -> 0 | U50: =T50-((R50-W50)/5) -> 0 | V50: =U50-((R50-W50)/5) -> 0 | W50: 0 | X50: =W50-((W50-AB50)/5) -> 0 | Y50: =X50-((W50-AB50)/5) -> 0 | Z50: =Y50-((W50-AB50)/5) -> 0 | AA50: =Z50-((W50-AB50)/5) -> 0 | AB50: 0 | AC50: =AB50-((AB50-AG50)/5) -> 0 | AD50: =AC50-((AB50-AG50)/5) -> 0 | AE50: =AD50-((AB50-AG50)/5) -> 0 | AF50: =AE50-((AB50-AG50)/5) -> 0 | AG50: 0 | AH50: =AG50-((AG50-AL50)/5) -> 0 | AI50: =AH50-((AG50-AL50)/5) -> 0 | AJ50: =AI50-((AG50-AL50)/5) -> 0 | AK50: =AJ50-((AG50-AL50)/5) -> 0 | AL50: 0 | AM50: =AL50-((AL50-AQ50)/5) -> 0 | AN50: =AM50-((AL50-AQ50)/5) -> 0 | AO50: =AN50-((AL50-AQ50)/5) -> 0 | AP50: =AO50-((AL50-AQ50)/5) -> 0 | AQ50: 0 | AR50: =AQ50-((AQ50-AV50)/5) -> 0 | AS50: =AR50-((AQ50-AV50)/5) -> 0 | AT50: =AS50-((AQ50-AV50)/5) -> 0 | AU50: =AT50-((AQ50-AV50)/5) -> 0 | AV50: 0 | AW50: =AV50-((AV50-BA50)/5) -> 0 | AX50: =AW50-((AV50-BA50)/5) -> 0 | AY50: =AX50-((AV50-BA50)/5) -> 0 | AZ50: =AY50-((AV50-BA50)/5) -> 0 | BA50: 0 | BB50: =BA50-((BA50-BF50)/5) -> 0 | BC50: =BB50-((BA50-BF50)/5) -> 0 | BD50: =BC50-((BA50-BF50)/5) -> 0 | BE50: =BD50-((BA50-BF50)/5) -> 0 | BF50: 0 | BG50: =BF50-((BF50-BK50)/5) -> 0 | BH50: =BG50-((BF50-BK50)/5) -> 0 | BI50: =BH50-((BF50-BK50)/5) -> 0 | BJ50: =BI50-((BF50-BK50)/5) -> 0 | BK50: 0 | BL50: =BK50-((BK50-BP50)/5) -> 0 | BM50: =BL50-((BK50-BP50)/5) -> 0 | BN50: =BM50-((BK50-BP50)/5) -> 0 | BO50: =BN50-((BK50-BP50)/5) -> 0 | BP50: 0 | BQ50: =BP50-((BP50-BU50)/5) -> 0 | BR50: =BQ50-((BP50-BU50)/5) -> 0 | BS50: =BR50-((BP50-BU50)/5) -> 0 | BT50: =BS50-((BP50-BU50)/5) -> 0 | BU50: 0 | BV50: =BU50-((BU50-BZ50)/5) -> 0 | BW50: =BV50-((BU50-BZ50)/5) -> 0 | BX50: =BW50-((BU50-BZ50)/5) -> 0 | BY50: =BX50-((BU50-BZ50)/5) -> 0 | BZ50: 0 | CA50: =BZ50-((BZ50-CE50)/5) -> 0 | CB50: =CA50-((BZ50-CE50)/5) -> 0 | CC50: =CB50-((BZ50-CE50)/5) -> 0 | CD50: =CC50-((BZ50-CE50)/5) -> 0 | CE50: 0 | CF50: =CE50-((CE50-CJ50)/5) -> 3 | CG50: =CF50-((CE50-CJ50)/5) -> 6 | CH50: =CG50-((CE50-CJ50)/5) -> 9 | CI50: =CH50-((CE50-CJ50)/5) -> 12 | CJ50: 15 | CK50: =CJ50-((CJ50-CO50)/5) -> 15 | CL50: =CK50-((CJ50-CO50)/5) -> 15 | CM50: =CL50-((CJ50-CO50)/5) -> 15 | CN50: =CM50-((CJ50-CO50)/5) -> 15 | CO50: 15 | CP50: =CO50-((CO50-CT50)/5) -> 15 | CQ50: =CP50-((CO50-CT50)/5) -> 15 | CR50: =CQ50-((CO50-CT50)/5) -> 15 | CS50: =CR50-((CO50-CT50)/5) -> 15 | CT50: 15 | CU50: =CT50-((CT50-CY50)/5) -> 15 | CV50: =CU50-((CT50-CY50)/5) -> 15 | CW50: =CV50-((CT50-CY50)/5) -> 15 | CX50: =CW50-((CT50-CY50)/5) -> 15 | CY50: 15 | CZ50: =CY50-((CY50-DD50)/5) -> 15 | DA50: =CZ50-((CY50-DD50)/5) -> 15 | DB50: =DA50-((CY50-DD50)/5) -> 15 | DC50: =DB50-((CY50-DD50)/5) -> 15 | DD50: 15 | DE50: =DD50-((DD50-DI50)/5) -> 15 | DF50: =DE50-((DD50-DI50)/5) -> 15 | DG50: =DF50-((DD50-DI50)/5) -> 15 | DH50: =DG50-((DD50-DI50)/5) -> 15 | DI50: 15 | DJ50: =DI50-((DI50-DN50)/5) -> 15 | DK50: =DJ50-((DI50-DN50)/5) -> 15 | DL50: =DK50-((DI50-DN50)/5) -> 15 | DM50: =DL50-((DI50-DN50)/5) -> 15 | DN50: 15 | DO50: =DN50-((DN50-DS50)/5) -> 15 | DP50: =DO50-((DN50-DS50)/5) -> 15 | DQ50: =DP50-((DN50-DS50)/5) -> 15 | DR50: =DQ50-((DN50-DS50)/5) -> 15 | DS50: 15 | DT50: =DS50-((DS50-DX50)/5) -> 15 | DU50: =DT50-((DS50-DX50)/5) -> 15 | DV50: =DU50-((DS50-DX50)/5) -> 15 | DW50: =DV50-((DS50-DX50)/5) -> 15 | DX50: 15 | DY50: =DX50-((DX50-EC50)/5) -> 15 | DZ50: =DY50-((DX50-EC50)/5) -> 15 | EA50: =DZ50-((DX50-EC50)/5) -> 15 | EB50: =EA50-((DX50-EC50)/5) -> 15 | EC50: 15
...

Sheet Data
B3: 1 | C3: =B3+1 -> 2 | D3: =C3+1 -> 3 | E3: =D3+1 -> 4 | F3: =E3+1 -> 5 | G3: =F3+1 -> 6 | H3: =G3+1 -> 7 | I3: =H3+1 -> 8 | J3: =I3+1 -> 9 | ... AD3: =AC3+1 -> 29
B5: Total Dwellings | D5: 1901 | E5: =D5+5 -> 1906 | F5: =E5+5 -> 1911 | G5: =F5+5 -> 1916 | H5: =G5+5 -> 1921 | I5: =H5+5 -> 1926 | J5: =I5+5 -> 1931 | K5: =J5+5 -> 1936 | L5: =K5+5 -> 1941 | ... AD5: =AC5+5 -> 2031
B6: AUS | C6: 0.02 | D6: 1000 | E6: =D6*(1+$C6)^5 -> 1104.0808 | F6: =E6*(1+$C6)^5 -> 1218.9944 | G6: =F6*(1+$C6)^5 -> 1345.8683 | H6: =G6*(1+$C6)^5 -> 1485.9474 | I6: =H6*(1+$C6)^5 -> 1640.606 | J6: =I6*(1+$C6)^5 -> 1811.3616 | K6: =J6*(1+$C6)^5 -> 1999.8896 | L6: =K6*(1+$C6)^5 -> 2208.0397 | ... AD6: =AC6*(1+$C6)^5 -> 13122.674
B7: WA | C7: 0.021 | D7: 100 | E7: =D7*(1+$C7)^5 -> 110.95036 | F7: =E7*(1+$C7)^5 -> 123.09982 | G7: =F7*(1+$C7)^5 -> 136.57969 | H7: =G7*(1+$C7)^5 -> 151.53566 | I7: =H7*(1+$C7)^5 -> 168.12936 | J7: =I7*(1+$C7)^5 -> 186.54012 | K7: =J7*(1+$C7)^5 -> 206.96694 | L7: =K7*(1+$C7)^5 -> 229.63056 | ... AD7: =AC7*(1+$C7)^5 -> 1490.5497
B8: 6008 | C8: 0.02 | D8: 5 | E8: =D8*(1+$C8)^5 -> 5.520404 | F8: =E8*(1+$C8)^5 -> 6.0949721 | G8: =F8*(1+$C8)^5 -> 6.7293417 | H8: =G8*(1+$C8)^5 -> 7.429737 | I8: =H8*(1+$C8)^5 -> 8.20303 | J8: =I8*(1+$C8)^5 -> 9.0568079 | K8: =J8*(1+$C8)^5 -> 9.9994478 | L8: =K8*(1+$C8)^5 -> 11.040198 | ... AD8: =AC8*(1+$C8)^5 -> 65.613368
B9: =B8+1 -> 6009 | C9: 0.022 | D9: 6 | E9: =D9*(1+$C9)^5 -> 6.6896859 | F9: =E9*(1+$C9)^5 -> 7.4586497 | G9: =F9*(1+$C9)^5 -> 8.316004 | H9: =G9*(1+$C9)^5 -> 9.2719091 | I9: =H9*(1+$C9)^5 -> 10.337693 | J9: =I9*(1+$C9)^5 -> 11.525987 | K9: =J9*(1+$C9)^5 -> 12.850872 | L9: =K9*(1+$C9)^5 -> 14.32805 | ... AD9: =AC9*(1+$C9)^5 -> 101.57053
B10: =B9+1 -> 6010 | C10: 0.02 | D10: 7 | E10: =D10*(1+$C10)^5 -> 7.7285656 | F10: =E10*(1+$C10)^5 -> 8.5329609 | G10: =F10*(1+$C10)^5 -> 9.4210784 | H10: =G10*(1+$C10)^5 -> 10.401632 | I10: =H10*(1+$C10)^5 -> 11.484242 | J10: =I10*(1+$C10)^5 -> 12.679531 | K10: =J10*(1+$C10)^5 -> 13.999227 | L10: =K10*(1+$C10)^5 -> 15.456278 | ... AD10: =AC10*(1+$C10)^5 -> 91.858716
B11: =B10+1 -> 6011 | C11: 0.019 | D11: 8 | E11: =D11*(1+$C11)^5 -> 8.789434 | F11: =E11*(1+$C11)^5 -> 9.6567687 | G11: =F11*(1+$C11)^5 -> 10.609691 | H11: =G11*(1+$C11)^5 -> 11.656648 | I11: =H11*(1+$C11)^5 -> 12.806917 | J11: =I11*(1+$C11)^5 -> 14.070694 | K11: =J11*(1+$C11)^5 -> 15.459179 | L11: =K11*(1+$C11)^5 -> 16.984679 | ... AD11: =AC11*(1+$C11)^5 -> 92.413179
B12: NSW | C12: 0.019 | D12: 300 | E12: =D12*(1+$C12)^5 -> 329.60377 | F12: =E12*(1+$C12)^5 -> 362.12882 | G12: =F12*(1+$C12)^5 -> 397.86342 | H12: =G12*(1+$C12)^5 -> 437.12428 | I12: =H12*(1+$C12)^5 -> 480.25938 | J12: =I12*(1+$C12)^5 -> 527.65101 | K12: =J12*(1+$C12)^5 -> 579.71921 | L12: =K12*(1+$C12)^5 -> 636.92547 | ... AD12: =AC12*(1+$C12)^5 -> 3465.4942
B13: 2070 | C13: 0.02 | D13: 5 | E13: =D13*(1+$C13)^5 -> 5.520404 | F13: =E13*(1+$C13)^5 -> 6.0949721 | G13: =F13*(1+$C13)^5 -> 6.7293417 | H13: =G13*(1+$C13)^5 -> 7.429737 | I13: =H13*(1+$C13)^5 -> 8.20303 | J13: =I13*(1+$C13)^5 -> 9.0568079 | K13: =J13*(1+$C13)^5 -> 9.9994478 | L13: =K13*(1+$C13)^5 -> 11.040198 | ... AD13: =AC13*(1+$C13)^5 -> 65.613368
B14: =B13+1 -> 2071 | C14: 0.021 | D14: 6 | E14: =D14*(1+$C14)^5 -> 6.6570215 | F14: =E14*(1+$C14)^5 -> 7.3859893 | G14: =F14*(1+$C14)^5 -> 8.1947816 | H14: =G14*(1+$C14)^5 -> 9.0921395 | I14: =H14*(1+$C14)^5 -> 10.087761 | J14: =I14*(1+$C14)^5 -> 11.192407 | K14: =J14*(1+$C14)^5 -> 12.418016 | L14: =K14*(1+$C14)^5 -> 13.777834 | ... AD14: =AC14*(1+$C14)^5 -> 89.432984
B15: =B14+1 -> 2072 | C15: 0.02 | D15: 7 | E15: =D15*(1+$C15)^5 -> 7.7285656 | F15: =E15*(1+$C15)^5 -> 8.5329609 | G15: =F15*(1+$C15)^5 -> 9.4210784 | H15: =G15*(1+$C15)^5 -> 10.401632 | I15: =H15*(1+$C15)^5 -> 11.484242 | J15: =I15*(1+$C15)^5 -> 12.679531 | K15: =J15*(1+$C15)^5 -> 13.999227 | L15: =K15*(1+$C15)^5 -> 15.456278 | ... AD15: =AC15*(1+$C15)^5 -> 91.858716
B16: =B15+1 -> 2073 | C16: 0.019 | D16: 8 | E16: =D16*(1+$C16)^5 -> 8.789434 | F16: =E16*(1+$C16)^5 -> 9.6567687 | G16: =F16*(1+$C16)^5 -> 10.609691 | H16: =G16*(1+$C16)^5 -> 11.656648 | I16: =H16*(1+$C16)^5 -> 12.806917 | J16: =I16*(1+$C16)^5 -> 14.070694 | K16: =J16*(1+$C16)^5 -> 15.459179 | L16: =K16*(1+$C16)^5 -> 16.984679 | ... AD16: =AC16*(1+$C16)^5 -> 92.413179
B17: =B16+1 -> 2074 | C17: 0.018 | D17: 9 | E17: =D17*(1+$C17)^5 -> 9.8396896 | F17: =E17*(1+$C17)^5 -> 10.757721 | G17: =F17*(1+$C17)^5 -> 11.761404 | H17: =G17*(1+$C17)^5 -> 12.85873 | I17: =H17*(1+$C17)^5 -> 14.058434 | J17: =I17*(1+$C17)^5 -> 15.37007 | K17: =J17*(1+$C17)^5 -> 16.80408 | L17: =K17*(1+$C17)^5 -> 18.371881 | ... AD17: =AC17*(1+$C17)^5 -> 91.506859
B18: =B17+1 -> 2075 | C18: 0.019 | D18: 10 | E18: =D18*(1+$C18)^5 -> 10.986792 | F18: =E18*(1+$C18)^5 -> 12.070961 | G18: =F18*(1+$C18)^5 -> 13.262114 | H18: =G18*(1+$C18)^5 -> 14.570809 | I18: =H18*(1+$C18)^5 -> 16.008646 | J18: =I18*(1+$C18)^5 -> 17.588367 | K18: =J18*(1+$C18)^5 -> 19.323974 | L18: =K18*(1+$C18)^5 -> 21.230849 | ... AD18: =AC18*(1+$C18)^5 -> 115.51647
D20: 0.99 | E20: =D20-1% -> 0.98 | F20: =E20-1% -> 0.97 | G20: =F20-1% -> 0.96 | H20: =G20-1% -> 0.95 | I20: =H20-1% -> 0.94 | J20: =I20-1% -> 0.93 | K20: =J20-1% -> 0.92 | L20: =K20-1% -> 0.91 | ... AD20: =AC20-1% -> 0.73
B21: Detached Dwellings | D21: 1901 | E21: =D21+5 -> 1906 | F21: =E21+5 -> 1911 | G21: =F21+5 -> 1916 | H21: =G21+5 -> 1921 | I21: =H21+5 -> 1926 | J21: =I21+5 -> 1931 | K21: =J21+5 -> 1936 | L21: =K21+5 -> 1941 | ... AD21: =AC21+5 -> 2031
B22: AUS | D22: =D6*D$20 -> 990 | E22: =E6*E$20 -> 1081.9992 | F22: =F6*F$20 -> 1182.4246 | G22: =G6*G$20 -> 1292.0336 | H22: =H6*H$20 -> 1411.65 | I22: =I6*I$20 -> 1542.1696 | J22: =J6*J$20 -> 1684.5663 | K22: =K6*K$20 -> 1839.8984 | ... AD22: =AD6*AD$20 -> 9579.5518
B23: WA | D23: =D7*D$20 -> 99 | E23: =E7*E$20 -> 108.73135 | F23: =F7*F$20 -> 119.40683 | G23: =G7*G$20 -> 131.11651 | H23: =H7*H$20 -> 143.95888 | I23: =I7*I$20 -> 158.0416 | J23: =J7*J$20 -> 173.48232 | K23: =K7*K$20 -> 190.40958 | ... AD23: =AD7*AD$20 -> 1088.1013
B24: 6008 | D24: =D8*D$20 -> 4.95 | E24: =E8*E$20 -> 5.4099959 | F24: =F8*F$20 -> 5.9121229 | G24: =G8*G$20 -> 6.460168 | H24: =H8*H$20 -> 7.0582501 | I24: =I8*I$20 -> 7.7108482 | J24: =J8*J$20 -> 8.4228314 | K24: =K8*K$20 -> 9.1994919 | ... AD24: =AD8*AD$20 -> 47.897759
B25: =B24+1 -> 6009 | D25: =D9*D$20 -> 5.94 | E25: =E9*E$20 -> 6.5558922 | F25: =F9*F$20 -> 7.2348902 | G25: =G9*G$20 -> 7.9833638 | H25: =H9*H$20 -> 8.8083137 | I25: =I9*I$20 -> 9.7174317 | J25: =J9*J$20 -> 10.719168 | K25: =K9*K$20 -> 11.822802 | ... AD25: =AD9*AD$20 -> 74.146484
B26: =B25+1 -> 6010 | D26: =D10*D$20 -> 6.93 | E26: =E10*E$20 -> 7.5739943 | F26: =F10*F$20 -> 8.2769721 | G26: =G10*G$20 -> 9.0442352 | H26: =H10*H$20 -> 9.8815502 | I26: =I10*I$20 -> 10.795187 | J26: =J10*J$20 -> 11.791964 | K26: =K10*K$20 -> 12.879289 | ... AD26: =AD10*AD$20 -> 67.056862
B27: =B26+1 -> 6011 | D27: =D11*D$20 -> 7.92 | E27: =E11*E$20 -> 8.6136453 | F27: =F11*F$20 -> 9.3670656 | G27: =G11*G$20 -> 10.185304 | H27: =H11*H$20 -> 11.073815 | I27: =I11*I$20 -> 12.038502 | J27: =J11*J$20 -> 13.085745 | K27: =K11*K$20 -> 14.222445 | ... AD27: =AD11*AD$20 -> 67.46162
B28: NSW | D28: =D12*D$20 -> 297 | E28: =E12*E$20 -> 323.0117 | F28: =F12*F$20 -> 351.26496 | G28: =G12*G$20 -> 381.94889 | H28: =H12*H$20 -> 415.26807 | I28: =I12*I$20 -> 451.44382 | J28: =J12*J$20 -> 490.71544 | K28: =K12*K$20 -> 533.34168 | ... AD28: =AD12*AD$20 -> 2529.8108
B29: 2070 | D29: =D13*D$20 -> 4.95 | E29: =E13*E$20 -> 5.4099959 | F29: =F13*F$20 -> 5.9121229 | G29: =G13*G$20 -> 6.460168 | H29: =H13*H$20 -> 7.0582501 | I29: =I13*I$20 -> 7.7108482 | J29: =J13*J$20 -> 8.4228314 | K29: =K13*K$20 -> 9.1994919 | ... AD29: =AD13*AD$20 -> 47.897759
B30: =B29+1 -> 2071 | D30: =D14*D$20 -> 5.94 | E30: =E14*E$20 -> 6.5238811 | F30: =F14*F$20 -> 7.1644096 | G30: =G14*G$20 -> 7.8669903 | H30: =H14*H$20 -> 8.6375326 | I30: =I14*I$20 -> 9.4824957 | J30: =J14*J$20 -> 10.408939 | K30: =K14*K$20 -> 11.424575 | ... AD30: =AD14*AD$20 -> 65.286078
B31: =B30+1 -> 2072 | D31: =D15*D$20 -> 6.93 | E31: =E15*E$20 -> 7.5739943 | F31: =F15*F$20 -> 8.2769721 | G31: =G15*G$20 -> 9.0442352 | H31: =H15*H$20 -> 9.8815502 | I31: =I15*I$20 -> 10.795187 | J31: =J15*J$20 -> 11.791964 | K31: =K15*K$20 -> 12.879289 | ... AD31: =AD15*AD$20 -> 67.056862
B32: =B31+1 -> 2073 | D32: =D16*D$20 -> 7.92 | E32: =E16*E$20 -> 8.6136453 | F32: =F16*F$20 -> 9.3670656 | G32: =G16*G$20 -> 10.185304 | H32: =H16*H$20 -> 11.073815 | I32: =I16*I$20 -> 12.038502 | J32: =J16*J$20 -> 13.085745 | K32: =K16*K$20 -> 14.222445 | ... AD32: =AD16*AD$20 -> 67.46162
B33: =B32+1 -> 2074 | D33: =D17*D$20 -> 8.91 | E33: =E17*E$20 -> 9.6428958 | F33: =F17*F$20 -> 10.43499 | G33: =G17*G$20 -> 11.290948 | H33: =H17*H$20 -> 12.215793 | I33: =I17*I$20 -> 13.214928 | J33: =J17*J$20 -> 14.294165 | K33: =K17*K$20 -> 15.459754 | ... AD33: =AD17*AD$20 -> 66.800007
B34: =B33+1 -> 2075 | D34: =D18*D$20 -> 9.9 | E34: =E18*E$20 -> 10.767057 | F34: =F18*F$20 -> 11.708832 | G34: =G18*G$20 -> 12.73163 | H34: =H18*H$20 -> 13.842269 | I34: =I18*I$20 -> 15.048127 | J34: =J18*J$20 -> 16.357181 | K34: =K18*K$20 -> 17.778056 | ... AD34: =AD18*AD$20 -> 84.327025
B37: Dwelling type | C37: =Master!$C$354 -> 1 | D37: 1= Total, 2 = Detached
B38: Data selection | C38: =Master!$N$4 -> WA
D40: 1901 | E40: =D40+5 -> 1906 | F40: =E40+5 -> 1911 | G40: =F40+5 -> 1916 | H40: =G40+5 -> 1921 | I40: =H40+5 -> 1926 | J40: =I40+5 -> 1931 | K40: =J40+5 -> 1936 | L40: =K40+5 -> 1941 | ... AD40: =AC40+5 -> 2031
B41: Data selected | C41: Total | D41: =VLOOKUP($C$38,$B5:$AD18,D$3,TRUE) -> 300 | E41: =VLOOKUP($C$38,$B5:$AD18,E$3,TRUE) -> 329.60377 | F41: =VLOOKUP($C$38,$B5:$AD18,F$3,TRUE) -> 362.12882 | G41: =VLOOKUP($C$38,$B5:$AD18,G$3,TRUE) -> 397.86342 | H41: =VLOOKUP($C$38,$B5:$AD18,H$3,TRUE) -> 437.12428 | I41: =VLOOKUP($C$38,$B5:$AD18,I$3,TRUE) -> 480.25938 | J41: =VLOOKUP($C$38,$B5:$AD18,J$3,TRUE) -> 527.65101 | K41: =VLOOKUP($C$38,$B5:$AD18,K$3,TRUE) -> 579.71921 | ... AD41: =VLOOKUP($C$38,$B5:$AD18,AD$3,TRUE) -> 3465.4942
C42: Detached | D42: =VLOOKUP($C$38,$B21:$AD34,D$3,TRUE) -> 297 | E42: =VLOOKUP($C$38,$B21:$AD34,E$3,TRUE) -> 323.0117 | F42: =VLOOKUP($C$38,$B21:$AD34,F$3,TRUE) -> 351.26496 | G42: =VLOOKUP($C$38,$B21:$AD34,G$3,TRUE) -> 381.94889 | H42: =VLOOKUP($C$38,$B21:$AD34,H$3,TRUE) -> 415.26807 | I42: =VLOOKUP($C$38,$B21:$AD34,I$3,TRUE) -> 451.44382 | J42: =VLOOKUP($C$38,$B21:$AD34,J$3,TRUE) -> 490.71544 | K42: =VLOOKUP($C$38,$B21:$AD34,K$3,TRUE) -> 533.34168 | ... AD42: =VLOOKUP($C$38,$B21:$AD34,AD$3,TRUE) -> 2529.8108
B49: ABS numbers | C49: 2021 | E49: ABS: 2021 Census
B50: Total | C50: 10852
B51: Detached | C51: 7596
A52: => | B52: Detached | C52: =C51/C50 -> 0.69996314
B54: My numbers | C54: 2021
...

Sheet Fencing-timber
H1: Annual | Q1: Existing | R1: New builds | S1: Total
B2: Rear fences | D2: Existing | F2: New builds | H2: Total | L2: Project number selected | N2: =#REF! -> #REF! | O2: =#REF! -> #REF! | Q2: =#REF! -> #REF! | R2: =#REF! -> #REF! | S2: =Q2+R2 -> #REF!
B3: Dwellings with projects | C3: # | D3: 172180 | F3: 133456
A4: x | B4: Side fences / dwelling | C4: # | D4: 0.5 | F4: 0.5
A5: x | B5: Timber | D5: 0.95 | F5: 0.8
A6: = | B6: Replaced / built annually | C6: # | D6: =D3*D4*D5 -> 81785.5 | F6: =F3*F4*F5 -> 53382.4 | H6: =D6+F6 -> 135167.9
A7: x | B7: Rear boundary | C7: m | D7: 22 | F7: 14
A8: = | B8: Length replaced / built annually | C8: m | D8: =D6*D7 -> 1799281 | F8: =F6*F7 -> 747353.6 | H8: =D8+F8 -> 2546634.6
A9: x | B9: Rear fence cost | C9: $/m | D9: 150 | F9: =D9 -> 150
A10: => | B10: Rear fence cost | C10: $/yr | D10: =D8*D9 -> 269892150 | F10: =F8*F9 -> 112103040 | G10: $/yr | H10: =D10+F10 -> 381995190
L11: Average block sizes
H12: Annual | L12: Existing | M12: New builds | Q12: Existing | R12: New builds
B13: Side fences (full boundary) | D13: Existing | F13: New builds | H13: Total | K13: m | L13: =D7 -> 22 | M13: =F7 -> 14 | P13: Front setback = | Q13: 10 | R13: 6
B14: Dwellings with projects | C14: # | D14: =D3 -> 172180 | F14: =F3 -> 133456 | K14: m | L14: =D19 -> 40 | M14: =F19 -> 35
A15: x | B15: Side fences / dwelling | C15: # | D15: 1 | F15: 1 | K15: m2 | L15: =L13*L14 -> 880 | M15: =M13*M14 -> 490
A16: x | B16: Side fences (full boundary) | D16: 0.6 | F16: 0.2
A17: x | B17: Timber | D17: 0.95 | F17: 0.8
A18: = | B18: Replaced / built annually | C18: # | D18: =D14*D15*D16*D17 -> 98142.6 | F18: =F14*F15*F16*F17 -> 21352.96 | H18: =D18+F18 -> 119495.56 | L18: HIA: | M18: file:///C:/Users/graem/Downloads/summary-of-hia-forecasts%20(1).pdf | T18: 44866
A19: x | B19: Side boundary (x1) | C19: m | D19: 40 | F19: 35
A20: => | B20: Length replaced / built annually | C20: m | D20: =D18*D19 -> 3925704 | F20: =F18*F19 -> 747353.6 | H20: =D20+F20 -> 4673057.6
A21: x | B21: Side fence cost | C21: $/m | D21: =D9 -> 150 | F21: =F9 -> 150
A22: => | B22: Side fence cost | C22: $/yr | D22: =D20*D21 -> 5.888556e+08 | F22: =F20*F21 -> 1.1210304e+08 | G22: $/yr | H22: =D22+F22 -> 7.0095864e+08
H24: Annual
B25: Side fences (from setback) | D25: Existing | F25: New builds | H25: Total
B26: Dwellings with projects | C26: # | D26: =D3 -> 172180 | F26: =F3 -> 133456
A27: x | B27: Side fences / dwelling | C27: # | D27: =D15 -> 1 | F27: =F15 -> 1
A28: x | B28: Side fences (from setback) | D28: =1-D16 -> 0.4 | F28: =1-F16 -> 0.8
A29: x | B29: Timber | D29: 0.95 | F29: 0.8
A30: = | B30: Replaced / built annually | C30: # | D30: =D26*D27*D28*D29 -> 65428.4 | F30: =F26*F27*F28*F29 -> 85411.84 | H30: =D30+F30 -> 150840.24
A31: x | B31: Side boundary (x1) | C31: m | D31: =D19-$Q13 -> 30 | F31: =F19-$R13 -> 29
A32: => | B32: Length replaced / built annually | C32: m | D32: =D30*D31 -> 1962852 | F32: =F30*F31 -> 2476943.4 | H32: =D32+F32 -> 4439795.4
A33: x | B33: Side fence cost | C33: $/m | D33: =D9 -> 150 | F33: =F9 -> 150
A34: => | B34: Side fence cost | C34: $/yr | D34: =D32*D33 -> 2.944278e+08 | F34: =F32*F33 -> 3.715415e+08 | G34: $/yr | H34: =D34+F34 -> 665969304
H36: Annual
B37: Front fences | D37: Existing | F37: New builds | H37: Total
B38: Dwellings with projects | C38: # | D38: 70282 | F38: 6740 | H38: =D38+F38 -> 77022
A39: x | B39: Front fences / dwelling | D39: 1 | F39: 1
A40: x | B40: Timber | D40: 0.5 | F40: 0.3
A41: = | B41: Replaced / built annually | C41: # | D41: =D38*D39*D40 -> 35141 | F41: =F38*F39*F40 -> 2022 | H41: =D41+F41 -> 37163
A42: x | B42: Front boundary | C42: m | D42: =D7 -> 22 | F42: =F7 -> 14
...
